Workbook

Sheet Компоненты
A1: ID | B1: Узел | C1: Функция | D1: Тип позиции | E1: Входит в модуль (ID) | F1: Название | G1: Определённость названия | H1: Статус решения | I1: № спорного пункта | J1: Кол-во на канал | K1: Число каналов | L1: Всего | M1: Сторона | N1: Размещение | O1: Ссылка | P1: Цена за шт., ₽ | Q1: Есть, шт. | R1: Докупить, шт. | S1: Стоимость докупки, ₽ | T1: Аккуратно! | U1: Источник | V1: Примечание
A2: E-001 | B2: Питание | C2: Блок питания 220 → 24 В (внешний адаптер) | D2: Модуль | F2: Mean Well GST220A24-R7B, 24 В, 9,2 А, 221 Вт, штекер DIN 4-pin (R7B) | G2: Выбран | H2: Утверждено | J2: 1 | K2: 1 | L2: =J2*K2 -> 1 | M2: Силовая | N2: — | O2: https://www.chipdip.ru/product/gst220a24-r7b-blok-pitaniya-24b-9.2a-221vt-mean-well-9000420376 | P2: 5860 | Q2: 0 | R2: =IF(D2="Внутри модуля",0,MAX(0,L2-Q2)) -> 1 | S2: =R2*P2 -> 5860 | T2: Нет | U2: чат 15.09 (утверждено Mikhail) | V2: Вне корпуса, «ноутбучная» схема: 220 В в стенд не заходит. Сетевой шнур C13 покупается отдельно. Прежний кандидат — Ecola LED 200 Вт IP20 (ozon.ru/t/higU70q), судьба уточняется
A3: E-002 | B3: Питание | C3: Кнопка включения питания (коммутирует катушку реле шины 24 В) | D3: Компонент | F3: Антивандальная 22 мм, с фиксацией, индикатор 24 В | G3: Выбран | H3: Утверждено | J3: 1 | K3: 1 | L3: =J3*K3 -> 1 | M3: Силовая | N3: Панель | O3: https://ozon.ru/t/zLw6TpD | P3: 376 | Q3: 0 | R3: =IF(D3="Внутри модуля",0,MAX(0,L3-Q3)) -> 1 | S3: =R3*P3 -> 376 | T3: Нет | U3: чат 15.09 (утверждено Mikhail) | V3: Через контакт — только ток катушки реле (замыкает A2 на GND_P); подсветка 24 В с выхода реле (горит, когда +24 подан). Разъём на PS — XP1 4-конт. (E-092): контакт 1–2, подсветка 3–4. Прежний — тумблер REXANT 15 А (ozon.ru/t/j7BR2sW), судьба уточняется
A4: E-003 | B4: Питание | C4: Предохранитель шины 24 В (после DC-гнезда, до реле) | D4: Компонент | F4: Предохранитель флажковый (ATO) 10 А + держатель на провод с крышкой АЭНК 8219 (до 30 А) | G4: Выбран | H4: Утверждено | J4: 1 | K4: 1 | L4: =J4*K4 -> 1 | M4: Силовая | N4: Корпус | O4: https://www.chipdip.ru/product/8219-derzhatel-predohranitelya-flazhkovogo-avtoelektronika-8012694315 | P4: 0 | Q4: 0 | R4: =IF(D4="Внутри модуля",0,MAX(0,L4-Q4)) -> 1 | S4: =R4*P4 -> 0 | T4: Нет | U4: чат 15.09 (утверждено Mikhail) | V4: Внутри корпуса, врезается в линию +24 между DC-гнездом и реле NRP-15. Цена держателя не заполнена
A5: E-004 | B5: Питание | C5: TVS шины 24 В | D5: Компонент | F5: SMCJ26A (однонаправленный, 26 В, 1500 Вт) | G5: Выбран | H5: Утверждено | J5: 1 | K5: 1 | L5: =J5*K5 -> 1 | M5: Силовая | N5: PS | P5: 0 | Q5: 0 | R5: =IF(D5="Внутри модуля",0,MAX(0,L5-Q5)) -> 1 | S5: =R5*P5 -> 0 | T5: Нет | U5: доска + чат 15.09 (утверждено Mikhail) | V5: Параллельно шине +24 после предохранителя; ограничение ниже пределов XL4015E (38 В) и DRV8871 (45 В). SMBJ28A с доски отклонён (R-015)
A6: E-007 | B6: Питание | C6: DC-DC 24 → 5P (силовые 5 В) | D6: Модуль | F6: XL4015E, 5 А, регулируемый | G6: Выбран | H6: Утверждено | J6: 1 | K6: 1 | L6: =J6*K6 -> 1 | M6: Силовая | N6: PS | O6: https://ozon.ru/t/v0TomWG | P6: 189 | Q6: 0 | R6: =IF(D6="Внутри модуля",0,MAX(0,L6-Q6)) -> 1 | S6: =R6*P6 -> 189 | T6: Нет | U6: лист питания | V6: Выставить 5,0 В и зафиксировать; питает ТОЛЬКО +5P: катушки NRP-02 ×16 (~640 мА), оптореле, выходы 6N137. Остров — от E-010
A7: E-008 | B7: Питание | C7: Индикатор «+5P есть» | D7: Компонент | F7: Светодиод 2 В (жёлтый по реестру) | G7: Выбран | H7: Утверждено | J7: 1 | K7: 1 | L7: =J7*K7 -> 1 | M7: Силовая | N7: Панель | O7: https://ozon.ru/t/1fZdgL1 | P7: 68 | Q7: 0 | R7: =IF(D7="Внутри модуля",0,MAX(0,L7-Q7)) -> 1 | S7: =R7*P7 -> 68 | T7: Нет | U7: лист питания | V7: Цвет не фиксирован
A8: E-009 | B8: Питание | C8: Резистор индикатора +5P | D8: Компонент | F8: МЛТ-0,25 ±5 %, 150 Ом | G8: Выбран | H8: Утверждено | J8: 1 | K8: 1 | L8: =J8*K8 -> 1 | M8: Силовая | N8: PS | O8: https://ozon.ru/t/QWYR5Dy | P8: 84 | Q8: 0 | R8: =IF(D8="Внутри модуля",0,MAX(0,L8-Q8)) -> 1 | S8: =R8*P8 -> 84 | T8: Нет | U8: лист питания | V8: ≈20 мА
A9: E-010 | B9: Питание | C9: Изолированный DC-DC 24 → 5 (логический остров) | D9: Компонент | F9: Mornsun VRB2405YMD-10WR3 (24 → 5 В, 10 Вт / 2 А, стабилизированный, изоляция 1,5 кВ) | G9: Выбран | H9: Утверждено | J9: 1 | K9: 1 | L9: =J9*K9 -> 1 | M9: Граница | N9: PS | P9: 0 | Q9: 0 | R9: =IF(D9="Внутри модуля",0,MAX(0,L9-Q9)) -> 1 | S9: =R9*P9 -> 0 | T9: Нет | U9: чат 15.09 (утверждено Mikhail) | V9: Питается от шины +24 (не от XL4015E). Остров ≈0,4 А + линия схвата до 1 А (E-083). Выводы по datasheet Mornsun 2026.03 (YMD, 25,4 × 25,4): 1 Ctrl (свободен), 2 GND, 3 Vin, 4 +Vo, 5 нет вывода, 6 0V; вывод ⌀1,0, отверстие 1,5. B0505S-1W из реестра не используется (R-013)
A10: E-011 | B10: Питание | C10: Источник 3,3 В логики | D10: Компонент | F10: Пин 3V3 платы YD-ESP32-S3 (бортовой LDO 5→3,3 В, 1 А) | G10: Выбран | H10: Утверждено | J10: 1 | K10: 1 | L10: =J10*K10 -> 1 | M10: Логическая | N10: MC | P10: 0 | Q10: 0 | R10: =IF(D10="Внутри модуля",0,MAX(0,L10-Q10)) -> 1 | S10: =R10*P10 -> 0 | T10: Нет | U10: чат 15.09 (утверждено Mikhail) | V10: Отдельного компонента нет. Потребители: TCA9548A, подтяжки I2C/RST, подтяжка выхода оптрона KH (<20 мА)
A11: E-012 | B11: Питание | C11: Дроссель фильтра +5P (L1) | D11: Компонент | F11: Talema DPO-3.0-22 — тороид 22 мкГн, 3 А, 50 мОм, ⌀14 × 8 мм, выводы 0,5 мм | G11: Выбран | H11: Утверждено | J11: 1 | K11: 1 | L11: =J11*K11 -> 1 | M11: Силовая | N11: PS | O11: https://www.chipdip.ru/product/dpo-3-0-22-drossel-pomehopodavlyayuschiy-dpu-22mkgn-talema-8002552890 | P11: 0 | Q11: 0 | R11: =IF(D11="Внутри модуля",0,MAX(0,L11-Q11)) -> 1 | S11: =R11*P11 -> 0 | T11: Нет | U11: чат 17.09 (утверждено Mikhail) | V11: LC-фильтр пульсаций после модуля XL4015E вне его петли ОС: L1 + C1 (E-093) + C2 (E-094), f₀ ≈ 1,6 кГц; падение ≈ 50 мВ/А. Footprint L_Toroid_D20_P10.16mm. Цена не заполнена
A12: E-020 | B12: Контроллер | C12: Микроконтроллер | D12: Модуль | F12: YD-ESP32-S3 N16R8 DevKit (ESP32-S3-DevKitC-1 clone) | G12: Выбран | H12: Утверждено | J12: 1 | K12: 1 | L12: =J12*K12 -> 1 | M12: Логическая | N12: MC | O12: https://ozon.ru/t/Wcg9F9p | P12: 966 | Q12: 1 | R12: =IF(D12="Внутри модуля",0,MAX(0,L12-Q12)) -> 0 | S12: =R12*P12 -> 0 | T12: Да | U12: доска + чат 15.09 | V12: Распиновка принята («Аккуратно!»); ПК — родной USB GPIO19/20, запас CH343 GPIO43/44; VIN от изолированных +5; GPIO48 — концевик M1 (предложение)
A13: E-021 | B13: Контроллер | C13: Подтяжки главной шины I2C | D13: Компонент | F13: МЛТ-0,25 ±5 %, 4,7 кОм (подтяжка к 3,3 В) | G13: Выбран | H13: Утверждено | J13: 2 | K13: 1 | L13: =J13*K13 -> 2 | M13: Логическая | N13: MC | P13: 0 | Q13: 0 | R13: =IF(D13="Внутри модуля",0,MAX(0,L13-Q13)) -> 2 | S13: =R13*P13 -> 0 | T13: Нет | U13: чат 20.09 (утверждено Mikhail) | V13: На модуле ESP32 подтяжек нет Утверждено 20.09.2026.
A14: E-022 | B14: I2C/датчики | C14: Мультиплексор I2C | D14: Модуль | F14: CJMCU-9548 (TCA9548A/PCA9548A) | G14: Выбран | H14: Утверждено | J14: 1 | K14: 1 | L14: =J14*K14 -> 1 | M14: Логическая | N14: MC | O14: https://ozon.ru/t/QWYQvBC | P14: 518 | Q14: 1 | R14: =IF(D14="Внутри модуля",0,MAX(0,L14-Q14)) -> 0 | S14: =R14*P14 -> 0 | T14: Нет | U14: доска + чат 15.09 | V14: VCC 3,3 В; A2 GND; A0/A1 от ESP32 (GPIO47/38); каналы 0–3
A15: E-023 | B15: I2C/датчики | C15: Подтяжка RST мультиплексора | D15: Компонент | F15: МЛТ-0,25 ±5 %, 10 кОм (подтяжка к 3,3 В) | G15: Выбран | H15: Утверждено | J15: 1 | K15: 1 | L15: =J15*K15 -> 1 | M15: Логическая | N15: MC | P15: 0 | Q15: 0 | R15: =IF(D15="Внутри модуля",0,MAX(0,L15-Q15)) -> 1 | S15: =R15*P15 -> 0 | T15: Нет | U15: чат 15.09 | V15: + линия на GPIO42
A16: E-024 | B16: Режим ЛР | C16: Кнопка переключения режима KH | D16: Компонент | F16: EKF S-Pro67, 19 мм, с фиксатором, белая подсветка 24 В | G16: Выбран | H16: Утверждено | J16: 1 | K16: 1 | L16: =J16*K16 -> 1 | M16: Силовая | N16: Панель | O16: https://ozon.ru/t/3 QXN2ZT | P16: 487 | Q16: 0 | R16: =IF(D16="Внутри модуля",0,MAX(0,L16-Q16)) -> 1 | S16: =R16*P16 -> 487 | T16: Нет | U16: чат 15.09 (утверждено Mikhail) | V16: Контакт коммутирует +5P на шину KH; подсветка от +24 с PS (XP5, E-018) кабелем напрямую к кнопке, минуя плату LR. Уточнить группу контактов (нужен 1×NO)
A17: E-025 | B17: Режим ЛР | C17: Подтяжка шины KH на землю | D17: Компонент | F17: МЛТ-0,25 ±5 %, 1 кОм | G17: Выбран | H17: Утверждено | J17: 1 | K17: 1 | L17: =J17*K17 -> 1 | M17: Силовая | N17: MC | O17: https://ozon.ru/t/gmtx6pg | P17: 79 | Q17: 0 | R17: =IF(D17="Внутри модуля",0,MAX(0,L17-Q17)) -> 1 | S17: =R17*P17 -> 79 | T17: Нет | U17: лист питания
A18: E-026 | B18: Режим ЛР | C18: Оптореле сигнала KH → ESP32 | D18: Компонент | F18: КР293КП2Б (из запаса: в реестре 12 шт., на RELE нужно 4) | G18: Выбран | H18: Утверждено | J18: 1 | K18: 1 | L18: =J18*K18 -> 1 | M18: Граница | N18: MC | O18: https://ozon.ru/t/sXzB21l | P18: 73 | Q18: 0 | R18: =IF(D18="Внутри модуля",0,MAX(0,L18-Q18)) -> 1 | S18: =R18*P18 -> 73 | T18: Нет | U18: чат 15.09 (утверждено Mikhail) | V18: Статический сигнал — скорость не важна; выход замыкает GPIO41 на GND_L; вход инвертный (в ПО). PC817 отклонён (R-014)
A19: E-027 | B19: Режим ЛР | C19: Резисторы оптореле KH | D19: Компонент | F19: МЛТ-0,25 ±5 %, 470 Ом (LED, от шины KH 5 В, ~8 мА) + 10 кОм (подтяжка GPIO41 к 3,3 В) | G19: Выбран | H19: Утверждено | J19: 2 | K19: 1 | L19: =J19*K19 -> 2 | M19: Граница | N19: MC | P19: 0 | Q19: 0 | R19: =IF(D19="Внутри модуля",0,MAX(0,L19-Q19)) -> 2 | S19: =R19*P19 -> 0 | T19: Нет | U19: чат 19.09 (утверждено Mikhail) | V19: Номиналы — предложение под КР293КП2Б (LED ≤10 мА) Утверждено 19.09.2026 в составе силовой части.
A20: E-030 | B20: Канал привода | C20: Драйвер ДПТ | D20: Модуль | F20: DRV8871 (модуль, клон Adafruit), 6,5–45 В | G20: Выбран | H20: Утверждено | J20: 1 | K20: 4 | L20: =J20*K20 -> 4 | M20: Силовая | N20: CH | O20: https://ozon.ru/t/tPvFr4r | P20: 0 | Q20: 4 | R20: =IF(D20="Внутри модуля",0,MAX(0,L20-Q20)) -> 0 | S20: =R20*P20 -> 0 | T20: Нет | U20: чат 19.09 (утверждено Mikhail) | V20: Ждёт мотора: до 3,6 А пик / ~2 А длит. Посадочное место сделать разъёмным Утверждено 19.09.2026 вместе с двигателем E-041 (1,2 А ном.): ток канала известен.
A21: E-031 | B21: Канал привода | C21: Микросхема драйвера на модуле | D21: Внутри модуля | E21: E-030 | F21: DRV8871DDAR | G21: Выбран | H21: Утверждено | J21: 1 | K21: 4 | L21: =J21*K21 -> 4 | M21: Силовая | N21: CH | P21: 0 | Q21: 0 | R21: =IF(D21="Внутри модуля",0,MAX(0,L21-Q21)) -> 0 | S21: =R21*P21 -> 0 | T21: Нет | U21: чат 19.09 (утверждено Mikhail) | V21: Приходит с модулем E-030 Утверждено 19.09.2026 вместе с двигателем E-041 (1,2 А ном.): ток канала известен.
A22: E-032 | B22: Канал привода | C22: Изолятор PWM IN1/IN2 | D22: Компонент | F22: 6N137 | G22: Выбран | H22: Утверждено | J22: 2 | K22: 4 | L22: =J22*K22 -> 8 | M22: Граница | N22: CH | P22: 0 | Q22: 0 | R22: =IF(D22="Внутри модуля",0,MAX(0,L22-Q22)) -> 8 | S22: =R22*P22 -> 0 | T22: Нет | U22: чат 14.09 | V22: Замена КР293КП2Б на PWM 20 кГц; выход инвертирующий (в ПО)
A23: E-033 | B23: Канал привода | C23: Резистор LED 6N137 | D23: Компонент | F23: МЛТ-0,25 ±5 %, 220 Ом | G23: Выбран | H23: Утверждено | J23: 2 | K23: 4 | L23: =J23*K23 -> 8 | M23: Логическая | N23: CH | P23: 0 | Q23: 0 | R23: =IF(D23="Внутри модуля",0,MAX(0,L23-Q23)) -> 8 | S23: =R23*P23 -> 0 | T23: Нет | U23: чат 14.09 | V23: Общий для ESP32 (3,3 В) и студента (3,3/5 В)
A24: E-034 | B24: Канал привода | C24: Подтяжка выхода 6N137 к +5P | D24: Компонент | F24: МЛТ-0,25 ±5 %, 4,7 кОм | G24: Выбран | H24: Утверждено | J24: 2 | K24: 4 | L24: =J24*K24 -> 8 | M24: Силовая | N24: CH | P24: 0 | Q24: 0 | R24: =IF(D24="Внутри модуля",0,MAX(0,L24-Q24)) -> 8 | S24: =R24*P24 -> 0 | T24: Нет | U24: чат 19.09 (утверждено Mikhail) | V24: Утверждено 19.09.2026 в составе силовой части.
A25: E-035 | B25: Канал привода | C25: Оптореле сигнала RELE | D25: Компонент | F25: КР293КП2Б | G25: Выбран | H25: Утверждено | J25: 1 | K25: 4 | L25: =J25*K25 -> 4 | M25: Граница | N25: CH | O25: https://ozon.ru/t/sXzB21l | P25: 73 | Q25: 0 | R25: =IF(D25="Внутри модуля",0,MAX(0,L25-Q25)) -> 4 | S25: =R25*P25 -> 292 | T25: Нет | U25: доска | V25: В реестре 12 шт. → нужно 4 (упаковка по 3)
A26: E-036 | B26: Канал привода | C26: Резистор LED оптореле | D26: Компонент | F26: МЛТ-0,25 ±5 %, 150 Ом | G26: Выбран | H26: Утверждено | J26: 1 | K26: 4 | L26: =J26*K26 -> 4 | M26: Логическая | N26: CH | O26: https://ozon.ru/t/QWYR5Dy | P26: 84 | Q26: 0 | R26: =IF(D26="Внутри модуля",0,MAX(0,L26-Q26)) -> 4 | S26: =R26*P26 -> 336 | T26: Нет | U26: доска | V26: ≤10 мА
A27: E-037 | B27: Канал привода | C27: Реле аварийного отключения питания ДПТ | D27: Компонент | F27: HF49FD/005-1H11 (Hongfa, 5 В, 5 А, 30 В DC) | G27: Выбран | H27: Утверждено | J27: 1 | K27: 4 | L27: =J27*K27 -> 4 | M27: Силовая | N27: CH | O27: https://ozon.ru/t/ukwD77G | P27: 108 | Q27: 0 | R27: =IF(D27="Внутри модуля",0,MAX(0,L27-Q27)) -> 4 | S27: =R27*P27 -> 432 | T27: Нет | U27: чат 19.09 (утверждено Mikhail) | V27: Годится только при стопорном токе мотора ≤ 5 А; катушка 24 мА через КР293КП2Б Утверждено 19.09.2026 вместе с двигателем E-041 (1,2 А ном.): ток канала известен.
A28: E-038 | B28: Канал привода | C28: Датчик тока | D28: Модуль | F28: ACS712-20A (модуль), 100 мВ/А | G28: Выбран | H28: Утверждено | J28: 1 | K28: 4 | L28: =J28*K28 -> 4 | M28: Граница | N28: CH | O28: https://ozon.ru/t/1fZ9B9H | P28: 130 | Q28: 4 | R28: =IF(D28="Внутри модуля",0,MAX(0,L28-Q28)) -> 0 | S28: =R28*P28 -> 0 | T28: Нет | U28: доска + чат 14.09 | V28: Сигнальная часть — логические +5; измеряемая цепь — силовая
A29: E-039 | B29: Канал привода | C29: Микросхема датчика тока на модуле | D29: Внутри модуля | E29: E-038 | F29: ACS712ELCTR-20A | G29: Выбран | H29: Утверждено | J29: 1 | K29: 4 | L29: =J29*K29 -> 4 | M29: Граница | N29: CH | P29: 0 | Q29: 0 | R29: =IF(D29="Внутри модуля",0,MAX(0,L29-Q29)) -> 0 | S29: =R29*P29 -> 0 | T29: Нет | U29: модуль | V29: Приходит с модулем E-038
A30: E-040 | B30: Канал привода | C30: Согласование выхода ACS712 с ADC ESP32 | D30: Компонент | F30: С2-23-0,25 ±1 %, делитель 10 кОм + 20 кОм | G30: Выбран | H30: Утверждено | J30: 2 | K30: 4 | L30: =J30*K30 -> 8 | M30: Логическая | N30: CH | P30: 0 | Q30: 0 | R30: =IF(D30="Внутри модуля",0,MAX(0,L30-Q30)) -> 8 | S30: =R30*P30 -> 0 | T30: Нет | U30: чат 19.09 (утверждено Mikhail) | V30: 0–5 В → 0–3,3 В; не утверждено Утверждено 19.09.2026 вместе с силовой частью.
A31: E-041 | B31: Канал привода | C31: Двигатель ДПТ 24 В | D31: Компонент | F31: Червячный мотор-редуктор NFP-5840-31ZY-DSH («2480»), 24 В, i = 670, двойной вал Ø8 мм, с фланцем | G31: Выбран | H31: Утверждено | J31: 1 | K31: 4 | L31: =J31*K31 -> 4 | M31: Силовая | N31: Звено | O31: https://market.yandex.ru/cc/B6zFNi | P31: 2184 | Q31: 0 | R31: =IF(D31="Внутри модуля",0,MAX(0,L31-Q31)) -> 4 | S31: =R31*P31 -> 8736 | T31: Да | U31: чат 19.09 (утверждено Mikhail) | V31: Червячный, самотормозящий. Паспорт класса (5840-31ZY, 24 В, i=670): 12 об/мин х.х., 9 об/мин и 70 кгс·см номинал, ток ≤1,2 А. Расчёт: M1 (вертикальная ось, J=2,77 кг·м² при вылете 1,21 м с грузом 0,5 кг) требует 3,1 Н·м при ε=1 рад/с² — запас ×2,2; звено 4 требует 2,35 Н·м, после двух ремней получаем 5,6 Н·м — запас ×2,4. Волновой редуктор i=8 НЕ ставится: дал бы 55 Н·м на печатном ABS-редукторе. Проверить у продавца стопорный ток (паспортные ≤1,6 А сомнительны) и что вал М8 — гладкий Ø8, а не резьба: под магнит AS5600 нужен ровный торец. Определяет (2), (6), (7), (16): по трём моторам M2…M4 токосъёмное кольцо ≥ 5 А. Отклонён FGA-43246000-G149 (4,5 А ном., ~20 А стоп) Модель по каталогу nfpshop.com (NFP-5840-31ZY-DSH).
A32: E-042 | B32: I2C/датчики | C32: Датчик положения звена | D32: Модуль | F32: AS5600 (модуль) | G32: Выбран | H32: Утверждено | J32: 1 | K32: 4 | L32: =J32*K32 -> 4 | M32: Логическая | N32: Звено | P32: 0 | Q32: 4 | R32: =IF(D32="Внутри модуля",0,MAX(0,L32-Q32)) -> 0 | S32: =R32*P32 -> 0 | T32: Нет | U32: доска | V32: Питание — логические +5/3,3 В (остров), не +5P; M2…M4 — через кольцо
A33: E-043 | B33: I2C/датчики | C33: Микросхема энкодера на модуле | D33: Внутри модуля | E33: E-042 | F33: AS5600-ASOM | G33: Выбран | H33: Утверждено | J33: 1 | K33: 4 | L33: =J33*K33 -> 4 | M33: Логическая | N33: Звено | P33: 0 | Q33: 0 | R33: =IF(D33="Внутри модуля",0,MAX(0,L33-Q33)) -> 0 | S33: =R33*P33 -> 0 | T33: Нет | U33: модуль | V33: Приходит с модулем E-042
A34: E-044 | B34: I2C/датчики | C34: Подтяжки I2C на модуле AS5600 | D34: Внутри модуля | E34: E-042 | F34: 10 кОм (типично для модулей) | G34: Кандидат | H34: Уточняется | J34: 2 | K34: 4 | L34: =J34*K34 -> 8 | M34: Логическая | N34: Звено | P34: 0 | Q34: 0 | R34: =IF(D34="Внутри модуля",0,MAX(0,L34-Q34)) -> 0 | S34: =R34*P34 -> 0 | T34: Нет | U34: чат 15.09 | V34: Проверить наличие на конкретном модуле; должны быть на стороне энкодера
A35: E-050 | B35: Режим ЛР | C35: Реле переключения режима (IN1, IN2, SDA, SCL) | D35: Компонент | F35: NRP-02-C-05DH, 5 В, SPDT, 3 А | G35: Выбран | H35: Утверждено | J35: 4 | K35: 4 | L35: =J35*K35 -> 16 | M35: Граница | N35: CH | O35: https://www.chipdip.ru/product/nrp-02-c-05dh-rele-1-pereklyuch-5vdc-3a-125vac-spdt-na-ncr-9000276611 | P35: 51 | Q35: 0 | R35: =IF(D35="Внутри модуля",0,MAX(0,L35-Q35)) -> 16 | S35: =R35*P35 -> 816 | T35: Нет | U35: доска + ChipDip | V35: Катушки от шины KH (+5P), ~40 мА каждая; сторона — граница: катушки от +5P, контакты в логических цепях
A36: E-098 | B36: Режим ЛР | C36: Разъём сигнальный 5 контактов | D36: Компонент | F36: JST B5B-XH-A (LF)(SN), вилка прямая на плату, XH, 2,5 мм, 5 контактов, 3 А | G36: Выбран | H36: Утверждено | J36: 9 | K36: 1 | L36: =J36*K36 -> 9 | M36: Логическая | N36: LR | P36: 0 | Q36: 0 | R36: =L36-Q36 -> 9 | S36: =R36*P36 -> 0 | T36: Нет | U36: чат 06.10 (утверждено Mikhail) | V36: LR X1…X8 (8 шт.) и CH X2 (1 шт.); позиция клемм ZP-001 (E-051) исключена 06.10.2026
A37: E-052 | B37: Режим ЛР | C37: Защита SDA/SCL разъёма ЛР — последовательный резистор | D37: Компонент | F37: МЛТ-0,25 ±5 %, 100 Ом | G37: Выбран | H37: Утверждено | J37: 2 | K37: 4 | L37: =J37*K37 -> 8 | M37: Логическая | N37: LR | P37: 0 | Q37: 0 | R37: =IF(D37="Внутри модуля",0,MAX(0,L37-Q37)) -> 8 | S37: =R37*P37 -> 0 | T37: Да | U37: чат 19.09 (утверждено Mikhail) | V37: Решение «добавить защиту» принято, номиналы — предложение Утверждено 19.09.2026 вместе с разъёмом ЛР.
A38: E-053 | B38: Режим ЛР | C38: Защита SDA/SCL разъёма ЛР — ограничитель | D38: Компонент | F38: BAT54S (сборка на 3,3 В и GND) | G38: Выбран | H38: Утверждено | J38: 2 | K38: 4 | L38: =J38*K38 -> 8 | M38: Логическая | N38: LR | P38: 0 | Q38: 0 | R38: =IF(D38="Внутри модуля",0,MAX(0,L38-Q38)) -> 8 | S38: =R38*P38 -> 0 | T38: Да | U38: чат 19.09 (утверждено Mikhail) | V38: Утверждено 19.09.2026 вместе с разъёмом ЛР.
A39: E-054 | B39: Режим ЛР | C39: Защита IN1/IN2 разъёма ЛР — встречный диод | D39: Компонент | F39: 1N4148 или аналог | G39: Выбран | H39: Утверждено | J39: 2 | K39: 4 | L39: =J39*K39 -> 8 | M39: Логическая | N39: LR | P39: 0 | Q39: 0 | R39: =IF(D39="Внутри модуля",0,MAX(0,L39-Q39)) -> 8 | S39: =R39*P39 -> 0 | T39: Да | U39: чат 19.09 (утверждено Mikhail) | V39: От отрицательного напряжения / переполюсовки на LED 6N137 Утверждено 19.09.2026 вместе с разъёмом ЛР.
A40: E-060 | B40: Индикация | C40: Расширитель портов для индикации | D40: Компонент | F40: PCF8574 (DIP или модуль) | G40: Выбран | H40: Утверждено | J40: 1 | K40: 1 | L40: =J40*K40 -> 1 | M40: Логическая | N40: LR | P40: 0 | Q40: 0 | R40: =IF(D40="Внутри модуля",0,MAX(0,L40-Q40)) -> 1 | S40: =R40*P40 -> 0 | T40: Да | U40: чат 20.09 (утверждено Mikhail) | V40: Принцип «через мультиплексор» утверждён; PCF8574 — предложение. 8 выходов = 4 двухцветных LED без запаса Утверждено 20.09.2026. Остаётся «Аккуратно!»: 8 выходов = ровно 4 двухцветных светодиода без запаса; под индикацию режима или аварии понадобится PCF8575 либо второй PCF8574.
...

Sheet Модули
A1: ID | B1: Название модуля | C1: Узел | D1: Статус | E1: Что уже на плате (см. «Внутри модуля») | F1: Что нужно рядом на нашей плате | G1: Нужно, шт. | H1: Есть, шт. | I1: Докупить | J1: Ссылка
A2: E-001 | B2: Mean Well GST220A24-R7B (внешний адаптер 24 В, 221 Вт) | C2: Питание | D2: Утверждено | E2: Сетевой вход C14, защиты КЗ/перегрузки/перенапряжения/перегрева, индикатор, штекер DIN 4-pin | F2: DC-гнездо E-014, предохранитель 10 А E-003, реле E-013 + диод E-015, кнопка E-002 | G2: =IFERROR(INDEX(Компоненты!$L:$L,MATCH(A2,Компоненты!$A:$A,0)),"") -> 1 | H2: =IFERROR(INDEX(Компоненты!$Q:$Q,MATCH(A2,Компоненты!$A:$A,0)),"") -> 0 | I2: =IFERROR(INDEX(Компоненты!$R:$R,MATCH(A2,Компоненты!$A:$A,0)),"") -> 1 | J2: https://www.chipdip.ru/product/gst220a24-r7b-blok-pitaniya-24b-9.2a-221vt-mean-well-9000420376
A3: E-007 | B3: XL4015E 24→5P | C3: Питание | D3: Утверждено | E3: XL4015E, дроссель, диод, подстроечник | F3: фильтр +5P, индикатор | G3: =IFERROR(INDEX(Компоненты!$L:$L,MATCH(A3,Компоненты!$A:$A,0)),"") -> 1 | H3: =IFERROR(INDEX(Компоненты!$Q:$Q,MATCH(A3,Компоненты!$A:$A,0)),"") -> 0 | I3: =IFERROR(INDEX(Компоненты!$R:$R,MATCH(A3,Компоненты!$A:$A,0)),"") -> 1 | J3: https://ozon.ru/t/v0TomWG
A4: E-020 | B4: YD-ESP32-S3 DevKit | C4: Контроллер | D4: Утверждено | E4: ESP32-S3-WROOM N16R8, LDO 3,3 В, CH343, USB-C ×2, кнопки BOOT/RST | F4: подтяжки I2C, гребёнки | G4: =IFERROR(INDEX(Компоненты!$L:$L,MATCH(A4,Компоненты!$A:$A,0)),"") -> 1 | H4: =IFERROR(INDEX(Компоненты!$Q:$Q,MATCH(A4,Компоненты!$A:$A,0)),"") -> 1 | I4: =IFERROR(INDEX(Компоненты!$R:$R,MATCH(A4,Компоненты!$A:$A,0)),"") -> 0 | J4: https://ozon.ru/t/Wcg9F9p
A5: E-022 | B5: CJMCU-9548 (TCA9548A) | C5: I2C/датчики | D5: Утверждено | E5: TCA9548A, подтяжки адресных входов | F5: 10 кОм на RST, питание 3,3 В | G5: =IFERROR(INDEX(Компоненты!$L:$L,MATCH(A5,Компоненты!$A:$A,0)),"") -> 1 | H5: =IFERROR(INDEX(Компоненты!$Q:$Q,MATCH(A5,Компоненты!$A:$A,0)),"") -> 1 | I5: =IFERROR(INDEX(Компоненты!$R:$R,MATCH(A5,Компоненты!$A:$A,0)),"") -> 0 | J5: https://ozon.ru/t/QWYQvBC
A6: E-030 | B6: DRV8871 модуль | C6: Канал привода | D6: Уточняется | E6: DRV8871, конденсатор VM, клеммники | F6: 6N137 ×2 с резисторами и подтяжками, реле HF49FD | G6: =IFERROR(INDEX(Компоненты!$L:$L,MATCH(A6,Компоненты!$A:$A,0)),"") -> 4 | H6: =IFERROR(INDEX(Компоненты!$Q:$Q,MATCH(A6,Компоненты!$A:$A,0)),"") -> 4 | I6: =IFERROR(INDEX(Компоненты!$R:$R,MATCH(A6,Компоненты!$A:$A,0)),"") -> 0 | J6: https://ozon.ru/t/tPvFr4r
A7: E-038 | B7: ACS712-20A модуль | C7: Канал привода | D7: Утверждено | E7: ACS712ELCTR-20A, фильтр, клеммник | F7: делитель 10к/20к на выход (предложение) | G7: =IFERROR(INDEX(Компоненты!$L:$L,MATCH(A7,Компоненты!$A:$A,0)),"") -> 4 | H7: =IFERROR(INDEX(Компоненты!$Q:$Q,MATCH(A7,Компоненты!$A:$A,0)),"") -> 4 | I7: =IFERROR(INDEX(Компоненты!$R:$R,MATCH(A7,Компоненты!$A:$A,0)),"") -> 0 | J7: https://ozon.ru/t/1fZ9B9H
A8: E-042 | B8: AS5600 модуль | C8: I2C/датчики | D8: Утверждено | E8: AS5600, подтяжки I2C (проверить), магнит | F8: реле NRP-02 ×2 на SDA/SCL, питание с острова | G8: =IFERROR(INDEX(Компоненты!$L:$L,MATCH(A8,Компоненты!$A:$A,0)),"") -> 4 | H8: =IFERROR(INDEX(Компоненты!$Q:$Q,MATCH(A8,Компоненты!$A:$A,0)),"") -> 4 | I8: =IFERROR(INDEX(Компоненты!$R:$R,MATCH(A8,Компоненты!$A:$A,0)),"") -> 0
A9: E-070 | B9: Pogo магнитный 2-pin | C9: Схват | D9: Уточняется | E9: — | F9: 4 пары на 7 контактов | G9: =IFERROR(INDEX(Компоненты!$L:$L,MATCH(A9,Компоненты!$A:$A,0)),"") -> 4 | H9: =IFERROR(INDEX(Компоненты!$Q:$Q,MATCH(A9,Компоненты!$A:$A,0)),"") -> 0 | I9: =IFERROR(INDEX(Компоненты!$R:$R,MATCH(A9,Компоненты!$A:$A,0)),"") -> 4 | J9: https://market.yandex.ru/cc/AwZszU
A11: Количества подтягиваются с листа «Компоненты» по ID (формулы INDEX/MATCH). Состав «что на плате» — текст; детализация — строки типа «Внутри модуля» на листе «Компоненты».

Sheet Отклонено
A1: ID | B1: Узел | C1: Что было предложено / стояло в реестре | D1: Чем заменено | E1: Причина | F1: Дата решения
A2: R-001 | B2: Питание | C2: Ступени DC-DC 24→12 В и 12→5 В (LM2596 → LM2672) | D2: XL4015E 24→5P напрямую | E2: DRV8871 питается от 24 В, 12 В не нужны | F2: 14.09.2026
A3: R-002 | B3: Режим ЛР | C3: Второй B0505S-1W в цепи KH + делитель 2×500 Ом → ESP-KH 2,5 В | D3: Оптрон (PC817 — предложение) | E3: Уровень 2,5 В на границе порога ESP32; изолированный DC-DC ради одного сигнала избыточен | F3: 14.09.2026
A4: R-003 | B4: Канал привода | C4: КР293КП2Б на входах IN1/IN2 драйвера | D4: 6N137 | E4: Время переключения ~1 мс не пропускает PWM 20 кГц | F4: 14.09.2026
A5: R-004 | B5: Индикация | C5: Красный LED + 50 Ом напрямую с GPIO ESP32 (ESP-Mx-VD ×4) | D5: Двухцветные LED через PCF8574 | E5: 50 Ом → 26 мА с GPIO (выше нормы); экономия выводов | F5: 14–15.09.2026
A6: R-005 | B6: Режим ЛР | C6: Тумблер REXANT как переключатель KH | D6: Кнопка с фиксацией и подсветкой 24 В | E6: Решение по эргономике (фото) | F6: 14.09.2026
A7: R-006 | B7: Схват | C7: Собственный изолированный DC-DC в схвате из +24 В для логики | D7: Логика схвата от изолированных +5 основания | E7: Потребовал бы изолятора UART в основании | F7: 14.09.2026
A8: R-007 | B8: Схват | C8: CAN / I2C как интерфейс до схвата | D8: UART (RX/TX, 3,3 В TTL) | E8: Проще; 6 проводов | F8: 14.09.2026
A9: R-008 | B9: Канал привода | C9: Канал привода M5 в основании (5-й DRV8871, ACS712, канал мультиплексора) | D9: Электроника M5 в съёмном схвате, данные по UART | E9: Схват — съёмный модуль с собственной электроникой | F9: 14.09.2026
A10: R-009 | B10: Канал привода | C10: Оптроны 4-выводные ×20 на каждый PWM (схема курсового проекта) | D10: 6N137 ×8 + КР293КП2Б ×4 | E10: Зачёркнуто на доске; заменено рукописной схемой | F10: доска
A11: R-010 | B11: I2C/датчики | C11: Питание TCA9548A от +5 В | D11: 3,3 В | E11: Порог входов 0,7·VCC = 3,5 В — не видит уровни ESP32 | F11: 15.09.2026
A12: R-011 | B12: Контроллер | C12: USB через мост CH343 (UART0) как основной канал к ПК | D12: Родной USB ESP32-S3 (GPIO19/20) | E12: Решение Mikhail; CH343 — запасной вариант | F12: 15.09.2026
... A17: R-016 | B17: Питание | C17: Отдельный индикатор «+24 есть» на панели: светодиод E-005 + резистор 1 кОм E-006 (R1, XP4 на PS) | D17: Встроенная подсветка 24 В кнопки питания E-002 через 4-конт. разъём XP1 (E-092), питание с выхода реле | E17: Кнопка уже содержит индикатор 24 В; отдельный светодиод и резистор дублируют его | F17: 17.09.2026

Sheet Сводка
A1: Сводка по базе компонентов (формулы по листу «Компоненты»)
A3: Статус решения | B3: Позиций | C3: Всего шт. | D3: Докупить шт. | E3: Стоимость докупки, ₽
A4: Утверждено | B4: =COUNTIFS(Компоненты!$H:$H,A4) -> 59 | C4: =SUMIFS(Компоненты!$L:$L,Компоненты!$H:$H,A4) -> 193 | D4: =SUMIFS(Компоненты!$R:$R,Компоненты!$H:$H,A4) -> 167 | E4: =SUMIFS(Компоненты!$S:$S,Компоненты!$H:$H,A4) -> 18644
A5: Предложение | B5: =COUNTIFS(Компоненты!$H:$H,A5) -> 0 | C5: =SUMIFS(Компоненты!$L:$L,Компоненты!$H:$H,A5) -> 0 | D5: =SUMIFS(Компоненты!$R:$R,Компоненты!$H:$H,A5) -> 0 | E5: =SUMIFS(Компоненты!$S:$S,Компоненты!$H:$H,A5) -> 0
A6: Уточняется | B6: =COUNTIFS(Компоненты!$H:$H,A6) -> 5 | C6: =SUMIFS(Компоненты!$L:$L,Компоненты!$H:$H,A6) -> 15 | D6: =SUMIFS(Компоненты!$R:$R,Компоненты!$H:$H,A6) -> 7 | E6: =SUMIFS(Компоненты!$S:$S,Компоненты!$H:$H,A6) -> 600
A7: Итого | B7: =SUM(B4:B6) -> 64 | C7: =SUM(C4:C6) -> 208 | D7: =SUM(D4:D6) -> 174 | E7: =SUM(E4:E6) -> 19244
A10: Узел | B10: Позиций | C10: Всего шт. | D10: Из них уточняется | E10: Стоимость докупки, ₽
A11: Питание | B11: =COUNTIFS(Компоненты!$B:$B,A11) -> 20 | C11: =SUMIFS(Компоненты!$L:$L,Компоненты!$B:$B,A11) -> 31 | D11: =COUNTIFS(Компоненты!$B:$B,A11,Компоненты!$H:$H,"Уточняется") -> 0 | E11: =SUMIFS(Компоненты!$S:$S,Компоненты!$B:$B,A11) -> 7367
A12: Контроллер | B12: =COUNTIFS(Компоненты!$B:$B,A12) -> 4 | C12: =SUMIFS(Компоненты!$L:$L,Компоненты!$B:$B,A12) -> 10 | D12: =COUNTIFS(Компоненты!$B:$B,A12,Компоненты!$H:$H,"Уточняется") -> 0 | E12: =SUMIFS(Компоненты!$S:$S,Компоненты!$B:$B,A12) -> 0
A13: Канал привода | B13: =COUNTIFS(Компоненты!$B:$B,A13) -> 15 | C13: =SUMIFS(Компоненты!$L:$L,Компоненты!$B:$B,A13) -> 71 | D13: =COUNTIFS(Компоненты!$B:$B,A13,Компоненты!$H:$H,"Уточняется") -> 0 | E13: =SUMIFS(Компоненты!$S:$S,Компоненты!$B:$B,A13) -> 9822
A14: Режим ЛР | B14: =COUNTIFS(Компоненты!$B:$B,A14) -> 9 | C14: =SUMIFS(Компоненты!$L:$L,Компоненты!$B:$B,A14) -> 54 | D14: =COUNTIFS(Компоненты!$B:$B,A14,Компоненты!$H:$H,"Уточняется") -> 0 | E14: =SUMIFS(Компоненты!$S:$S,Компоненты!$B:$B,A14) -> 1455
A15: I2C/датчики | B15: =COUNTIFS(Компоненты!$B:$B,A15) -> 5 | C15: =SUMIFS(Компоненты!$L:$L,Компоненты!$B:$B,A15) -> 18 | D15: =COUNTIFS(Компоненты!$B:$B,A15,Компоненты!$H:$H,"Уточняется") -> 1 | E15: =SUMIFS(Компоненты!$S:$S,Компоненты!$B:$B,A15) -> 0
A16: Индикация | B16: =COUNTIFS(Компоненты!$B:$B,A16) -> 3 | C16: =SUMIFS(Компоненты!$L:$L,Компоненты!$B:$B,A16) -> 13 | D16: =COUNTIFS(Компоненты!$B:$B,A16,Компоненты!$H:$H,"Уточняется") -> 0 | E16: =SUMIFS(Компоненты!$S:$S,Компоненты!$B:$B,A16) -> 0
A17: Схват | B17: =COUNTIFS(Компоненты!$B:$B,A17) -> 5 | C17: =SUMIFS(Компоненты!$L:$L,Компоненты!$B:$B,A17) -> 8 | D17: =COUNTIFS(Компоненты!$B:$B,A17,Компоненты!$H:$H,"Уточняется") -> 3 | E17: =SUMIFS(Компоненты!$S:$S,Компоненты!$B:$B,A17) -> 600
A18: Кольцо/провода | B18: =COUNTIFS(Компоненты!$B:$B,A18) -> 3 | C18: =SUMIFS(Компоненты!$L:$L,Компоненты!$B:$B,A18) -> 3 | D18: =COUNTIFS(Компоненты!$B:$B,A18,Компоненты!$H:$H,"Уточняется") -> 1 | E18: =SUMIFS(Компоненты!$S:$S,Компоненты!$B:$B,A18) -> 0
A19: Итого | B19: =SUM(B11:B18) -> 64 | C19: =SUM(C11:C18) -> 208 | D19: =SUM(D11:D18) -> 5 | E19: =SUM(E11:E18) -> 19244
A22: Определённость названия | B22: Позиций
A23: Выбран | B23: =COUNTIFS(Компоненты!$G:$G,A23) -> 55
A24: Кандидат | B24: =COUNTIFS(Компоненты!$G:$G,A24) -> 2
A25: Только функция | B25: =COUNTIFS(Компоненты!$G:$G,A25) -> 7
A27: Тип позиции | B27: Позиций | C27: Всего шт.
A28: Модуль | B28: =COUNTIFS(Компоненты!$D:$D,A28) -> 8 | C28: =SUMIFS(Компоненты!$L:$L,Компоненты!$D:$D,A28) -> 20
A29: Компонент | B29: =COUNTIFS(Компоненты!$D:$D,A29) -> 52 | C29: =SUMIFS(Компоненты!$L:$L,Компоненты!$D:$D,A29) -> 168
A30: Внутри модуля | B30: =COUNTIFS(Компоненты!$D:$D,A30) -> 4 | C30: =SUMIFS(Компоненты!$L:$L,Компоненты!$D:$D,A30) -> 20
A32: Позиций с пометкой «Аккуратно!» | B32: =COUNTIFS(Компоненты!$T:$T,"Да") -> 7
A33: Отклонённых решений (лист «Отклонено») | B33: =COUNTA(Отклонено!$A:$A)-1 -> 16
A35: Открытые вопросы: на листе «Компоненты» фильтр Статус = «Уточняется» или Определённость = «Только функция». Что докупать: фильтр Докупить > 0.

Sheet Справочники
A1: Узел | B1: Тип позиции | C1: Определённость | D1: Статус | E1: Сторона | F1: Размещение | G1: Да/Нет
A2: Питание | B2: Модуль | C2: Выбран | D2: Утверждено | E2: Силовая | F2: MC | G2: Да
A3: Контроллер | B3: Компонент | C3: Кандидат | D3: Предложение | E3: Логическая | F3: PS | G3: Нет
A4: Канал привода | B4: Внутри модуля | C4: Только функция | D4: Уточняется | E4: Граница | F4: CH
A5: Режим ЛР | E5: — | F5: LR
A6: I2C/датчики | F6: GR
A7: Индикация | F7: Панель
A8: Схват | F8: Корпус
A9: Кольцо/провода | F9: Основание
F10: Звено
F11: Схват
A12: Списки используются проверкой данных на листе «Компоненты». Добавляя значение — дописывай сюда. | F12: —
F14: Коды плат: MC — главная (контроллер), PS — питание, CH — канал привода (×4+1), LR — панель ЛР, GR — схват
